Workbook

Sheet Стандарт k8s
A1: Стандарт
B2: Розрахунок ресурсів виконується лише для кількості ліцензій, кратної 25 (25, 50, 75, 100, 125 і тд.)
B4: Промислове середовище | D4: CPU | E4: RAM rec | F4: Кількість | G4: ОС | H4: Диск для ОС | J4: Диск для LDF, TEMPDB | L4: Диск для MainData | N4: Диск для Content | P4: IOPS 50r/50w | Q4: Lat. <=, mc
A5: К-ть ліцензій MSSQL | B5: Сервери | C5: от ГГц | D5: Ядер | E5: Гб | H5: тип | I5: Гб | J5: тип | K5: Гб | L5: тип | M5: Гб | N5: тип | O5: Гб
B6: SQL | C6: >=3.0 | D6: =IFERROR(VLOOKUP(A6,MSSQL!A2:E13,3,TRUE),"0") -> 0 | E6: =IFERROR(VLOOKUP(A6,MSSQL!A2:E13,5,TRUE),"0") -> 0 | F6: 1 | G6: Windows Server 2022 | H6: SSD | I6: 150 | J6: SSD | K6: 150* | L6: SSD | M6: 300* | N6: SATA | O6: 200* | P6: =IFERROR(VLOOKUP(A6,MSSQL!A2:G13,6,TRUE),"0") -> 0 | Q6: =IFERROR(VLOOKUP(A6,MSSQL!A2:G13,7,TRUE),"0") -> 0
B7: Master node | C7: >=3.0 | D7: 4 | E7: 6 | F7: 1 | G7: Ubuntu 24.04 | H7: SSD | I7: 100
B8: Worker-node | C8: >=3.0 | D8: 8 | E8: 32 | F8: =MAX(1,MAX(CEILING(D9/D8,1),CEILING(E9/E8,1))) -> 1 | G8: Ubuntu 24.04 | H8: SSD | I8: 200
B9: Загальна сума CPU/RAM worker-node | D9: =IF(ISNUMBER(A13),C24,0) + IF(ISNUMBER(A25),C32,0) + IF(ISNUMBER(A33),C39,0) + IF(ISNUMBER(A40),C45,0) -> 0 | E9: =IF(ISNUMBER(A13),D24,0) + IF(ISNUMBER(A25),D32,0) + IF(ISNUMBER(A33),D39,0) + IF(ISNUMBER(A40),D45,0) -> 0
A12: К-ть ліцензій
B13: Pods: | C13: CPU | D13: RAM | E13: Кількість
B14: AS (Сервер додатків) | C14: 1 | D14: 8 | E14: =ROUNDUP($A$13/25,0) -> 0
B15: AS-Local SQL | C15: 1 | D15: 3 | E15: 1 | H15: не маштабується
B16: AS-Redis | C16: 0.1 | D16: 0.1 | E16: 1 | H16: не маштабується
B17: ROBOT (Планувальник) | C17: 1 | D17: 8 | E17: =1+INT($A$13/100) + INT(A40/1000) -> 1
B18: ROBOT-Local SQL | C18: 1 | D18: 3 | E18: 1 | H18: не маштабується
B19: ROBOT-Redis | C19: 0.1 | D19: 0.1 | E19: 1 | H19: не маштабується
B20: Webrmd (Веб клієнт) | C20: 0.2 | D20: 1.5 | E20: =ROUNDUP($A$13/25,0) -> 0
B21: SmartID | C21: 0.2 | D21: 0.5 | E21: =ROUNDUP($A$13/25,0) -> 0
B22: WS (Веб сервіси) | C22: 0.25 | D22: 0.5 | E22: =1+INT($A$13/50) + INT(A40/500) -> 1
B23: WS-SignalR | C23: 0.25 | D23: 0.5 | E23: =ROUNDUP($A$13/25,0) -> 0
A24: К-ть ліцензій | C24: =SUMPRODUCT(C14:C23,E14:E23) -> 3.45 | D24: =SUMPRODUCT(D14:D23,E14:E23) -> 14.7
B25: ForceBPM | C25: CPU | D25: RAM | E25: Кількість
B26: GraphQL | C26: 0.3 | D26: 1 | E26: =ROUNDUP($A$25/25,0) -> 0
B27: ForceBPM Engine | C27: 1 | D27: 4 | E27: =1+INT($A$25/100) -> 1 | H27: не маштабується
B28: ForceBPM Modeler | C28: 0.5 | D28: 0.5 | E28: 1
B29: ForceBPM Processes | C29: 0.5 | D29: 2 | E29: =ROUNDUP($A$25/25,0) -> 0
B30: ForceBPM Tasks | C30: 0.3 | D30: 2 | E30: =ROUNDUP($A$25/25,0) -> 0
B31: ForceBPM Tasks-Graphql | C31: 0.3 | D31: 1 | E31: =ROUNDUP($A$25/25,0) -> 0
A32: К-ть сесій | C32: =SUMPRODUCT(C26:C31,E26:E31) -> 1.5 | D32: =SUMPRODUCT(D26:D31,E26:E31) -> 4.5
B33: LMS | C33: CPU | D33: RAM | E33: Кількість
B34: SmartID | C34: 0.006 | D34: 0.05 | E34: =ROUNDUP($A$33/25,0) -> 0
B35: LMS | C35: 0.3 | D35: 1 | E35: 1
B36: LMS-GraphQL | C36: 0.09 | D36: 0.3 | E36: =ROUNDUP($A$33/25,0) -> 0
B37: LMS-Videoutilities | C37: 4 | D37: 6 | E37: 1 | H37: Для пришвидшення треба збільшувати репліки (не маштабується)
B38: LMS-Fileserver | C38: 0.5 | D38: 8 | E38: 1
A39: К-ть сесій | C39: =SUMPRODUCT(C34:C38,E34:E38) -> 4.8 | D39: =SUMPRODUCT(D34:D38,E34:E38) -> 15
B40: HR Portal | C40: CPU | D40: RAM | E40: Кількість
B41: SmartID | C41: 0.006 | D41: 0.05 | E41: =ROUNDUP($A$40/100,0) -> 0
B42: GraphQL | C42: 0.01 | D42: 0.06 | E42: =ROUNDUP($A$40/100,0) -> 0
B43: WebAppModeler | C43: 0.5 | D43: 2 | E43: 1 | H43: не маштабується
...

Sheet Документообіг k8s
A1: Документообіг
B2: Розрахунок ресурсів виконується лише для кількості ліцензій, кратної 25 (25, 50, 75, 100, 125 і тд.)
B4: Промислове середовище (Документообіг) | D4: CPU | E4: RAM rec | F4: Кількість | G4: ОС | H4: Диск для ОС | J4: Диск для LDF, TEMPDB | L4: Диск для MainData | N4: Диск для Content | P4: IOPS 50r/50w | Q4: Lat. <=, mc
A5: К-ть ліцензій MSSQL | B5: Сервери | C5: от ГГц | D5: Ядер | E5: Гб | H5: тип | I5: Гб | J5: тип | K5: Гб | L5: тип | M5: Гб | N5: тип | O5: Гб
B6: SQL | C6: >=3.0 | D6: =IFERROR(VLOOKUP(A6,MSSQL!A17:G29,3,TRUE),"0") -> 0 | E6: =IFERROR(VLOOKUP(A6,MSSQL!A17:G29,5,TRUE),"0") -> 0 | F6: 1 | G6: Windows Server 2022 | H6: SSD | I6: 150 | J6: SSD | K6: 150* | L6: SSD | M6: 300* | N6: SATA | O6: 200* | P6: =IFERROR(VLOOKUP(A6,MSSQL!A17:G29,6,TRUE),"0") -> 0 | Q6: =IFERROR(VLOOKUP(A6,MSSQL!A17:G29,7,TRUE),"0") -> 0
B7: Master node | C7: >=3.0 | D7: 4 | E7: 6 | F7: 1 | G7: Ubuntu 24.04 | H7: SSD | I7: 100
B8: Worker-node | C8: >=3.0 | D8: 8 | E8: 32 | F8: =MAX(1,MAX(CEILING(D9/D8,1),CEILING(E9/E8,1))) -> 1 | G8: Ubuntu 24.04 | H8: SSD | I8: 200
B9: Загальна сума CPU/RAM worker-node | D9: =IF(ISNUMBER(A13),C24,0) + IF(ISNUMBER(A25),C32,0) + IF(ISNUMBER(A33),C39,0) + IF(ISNUMBER(A40),C45,0) -> 0 | E9: =IF(ISNUMBER(A13),D24,0) + IF(ISNUMBER(A25),D32,0) + IF(ISNUMBER(A33),D39,0) + IF(ISNUMBER(A40),D45,0) -> 0
A12: К-ть ліцензій
B13: Pods: | C13: CPU | D13: RAM | E13: Кількість
B14: AS (Сервер додатків) | C14: 1.3 | D14: 10 | E14: =ROUNDUP($A$13/25,0) -> 0
B15: AS-Local SQL | C15: 1 | D15: 5 | E15: 1 | H15: не маштабується
B16: AS-Redis | C16: 0.2 | D16: 0.2 | E16: 1 | H16: не маштабується
B17: ROBOT (Планувальник) | C17: 1.3 | D17: 10 | E17: =1+INT($A$13/100) + INT(A40/1000) -> 1
B18: ROBOT-Local SQL | C18: 1 | D18: 5 | E18: 1 | H18: не маштабується
B19: ROBOT-Redis | C19: 0.2 | D19: 0.2 | E19: 1 | H19: не маштабується
B20: Webrmd (Веб клієнт) | C20: 0.2 | D20: 1.5 | E20: =ROUNDUP($A$13/25,0) -> 0
B21: SmartID | C21: 0.2 | D21: 0.5 | E21: =ROUNDUP($A$13/25,0) -> 0
B22: WS (Веб сервіси) | C22: 0.35 | D22: 0.6 | E22: =1+INT($A$13/50) + INT(A40/500) -> 1
B23: WS-SignalR | C23: 0.25 | D23: 0.5 | E23: =ROUNDUP($A$13/25,0) -> 0
A24: К-ть ліцензій | C24: =SUMPRODUCT(C14:C23,E14:E23) -> 4.05 | D24: =SUMPRODUCT(D14:D23,E14:E23) -> 21
B25: ForceBPM | C25: CPU | D25: RAM | E25: Кількість
B26: GraphQL | C26: 0.3 | D26: 1 | E26: =ROUNDUP($A$25/25,0) -> 0
B27: ForceBPM Engine | C27: 1 | D27: 4 | E27: =1+INT($A$25/100) -> 1 | H27: не маштабується
B28: ForceBPM Modeler | C28: 0.5 | D28: 0.5 | E28: 1
B29: ForceBPM Processes | C29: 0.5 | D29: 2 | E29: =ROUNDUP($A$25/25,0) -> 0
B30: ForceBPM Tasks | C30: 0.3 | D30: 2 | E30: =ROUNDUP($A$25/25,0) -> 0
B31: ForceBPM Tasks-Graphql | C31: 0.3 | D31: 1 | E31: =ROUNDUP($A$25/25,0) -> 0
A32: К-ть сесій | C32: =SUMPRODUCT(C26:C31,E26:E31) -> 1.5 | D32: =SUMPRODUCT(D26:D31,E26:E31) -> 4.5
B33: LMS | C33: CPU | D33: RAM | E33: Кількість
B34: SmartID | C34: 0.006 | D34: 0.05 | E34: =ROUNDUP($A$33/25,0) -> 0
B35: LMS | C35: 0.3 | D35: 1 | E35: 1
B36: LMS-GraphQL | C36: 0.09 | D36: 0.3 | E36: =ROUNDUP($A$33/25,0) -> 0
B37: LMS-Videoutilities | C37: 4 | D37: 6 | E37: 1 | H37: Для пришвидшення треба збільшувати репліки (не маштабується)
B38: LMS-Fileserver | C38: 0.5 | D38: 8 | E38: 1
A39: К-ть сесій | C39: =SUMPRODUCT(C34:C38,E34:E38) -> 4.8 | D39: =SUMPRODUCT(D34:D38,E34:E38) -> 15
B40: HR Portal | C40: CPU | D40: RAM | E40: Кількість
B41: SmartID | C41: 0.006 | D41: 0.05 | E41: =ROUNDUP($A$40/100,0) -> 0
B42: GraphQL | C42: 0.01 | D42: 0.06 | E42: =ROUNDUP($A$40/100,0) -> 0
B43: WebAppModeler | C43: 0.5 | D43: 2 | E43: 1 | H43: не маштабується
...

Sheet MSSQL
A1: Мін ліцензій | B1: Макс ліцензій | C1: CPU (ядер) | D1: RAM Min | E1: RAM Rec | F1: IOPS 50/50 | G1: Latency | H1: Стандарт | I1: Кількість ліцензій | J1: CPU | K1: RAM min | L1: RAM rec | M1: IOPS | N1: Latency
A2: 1 | B2: 10 | C2: 2 | D2: 4 | E2: 8 | F2: 200 | G2: 8 | J2: =IFERROR(VLOOKUP(I2,A2:G13,3,TRUE),"Немає даних") -> Немає даних | K2: =IFERROR(VLOOKUP(I2,A2:G13,4,TRUE),"Немає даних") -> Немає даних | L2: =IFERROR(VLOOKUP(I2,A2:G13,5,TRUE),"Немає даних") -> Немає даних | M2: =IFERROR(VLOOKUP(I2,A2:G13,6,TRUE),"Немає даних") -> Немає даних | N2: =IFERROR(VLOOKUP(I2,A2:G13,7,TRUE),"Немає даних") -> Немає даних
A3: 11 | B3: 25 | C3: 4 | D3: 8 | E3: 12 | F3: 250 | G3: 7
A4: 26 | B4: 50 | C4: 6 | D4: 16 | E4: 24 | F4: 300 | G4: 5
A5: 51 | B5: 100 | C5: 8 | D5: 32 | E5: 48 | F5: 500 | G5: 4
A6: 101 | B6: 200 | C6: 10 | D6: 64 | E6: 96 | F6: 800 | G6: 3
A7: 201 | B7: 350 | C7: 12 | D7: 112 | E7: 168 | F7: 1400 | G7: 2
A8: 351 | B8: 500 | C8: 16 | D8: 168 | E8: 240 | F8: 2000 | G8: 1
A9: 501 | B9: 1000 | C9: 20 | D9: 240 | E9: 384 | F9: 4000 | G9: 0.6
A10: 1001 | B10: 2000 | C10: 22 | D10: 384 | E10: 576 | F10: 12000 | G10: 0.2
A11: 2001 | B11: 3000 | C11: 24 | D11: 576 | E11: 768 | F11: 24000 | G11: 0.1
A12: 3001 | B12: 4000 | C12: 28 | D12: 768 | E12: 960 | F12: 36000 | G12: 0.1
A13: 4001 | B13: 5000 | C13: 32 | D13: 960 | E13: 1152 | F13: 48000 | G13: 0.1
A16: Документообіг
A17: Мін ліцензій | B17: Макс ліцензій | C17: CPU (ядер) | D17: RAM Min | E17: RAM Rec | F17: IOPS 50/50 | G17: Latency | H17: Документообіг | I17: Кількість ліцензій | J17: CPU | K17: RAM min | L17: RAM rec | M17: IOPS | N17: Latency
A18: 1 | B18: 10 | C18: 2 | D18: 4 | E18: 8 | F18: 200 | G18: 8 | J18: =IFERROR(VLOOKUP(I18,A17:G29,3,TRUE),"Немає даних") -> Немає даних | K18: =IFERROR(VLOOKUP(I18,A17:G29,4,TRUE),"Немає даних") -> Немає даних | L18: =IFERROR(VLOOKUP(I18,A17:G29,5,TRUE),"Немає даних") -> Немає даних | M18: =IFERROR(VLOOKUP(I18,A17:G29,6,TRUE),"Немає даних") -> Немає даних | N18: =IFERROR(VLOOKUP(I18,A17:G29,7,TRUE),"Немає даних") -> Немає даних
A19: 11 | B19: 25 | C19: 4 | D19: 8 | E19: 12 | F19: 250 | G19: 7
A20: 26 | B20: 50 | C20: 4 | D20: 16 | E20: 24 | F20: 300 | G20: 5
A21: 51 | B21: 100 | C21: 6 | D21: 32 | E21: 48 | F21: 500 | G21: 4
A22: 101 | B22: 200 | C22: 6 | D22: 48 | E22: 64 | F22: 800 | G22: 3
A23: 201 | B23: 350 | C23: 8 | D23: 64 | E23: 96 | F23: 1400 | G23: 2
A24: 351 | B24: 500 | C24: 8 | D24: 96 | E24: 128 | F24: 2000 | G24: 1
A25: 501 | B25: 1000 | C25: 12 | D25: 128 | E25: 192 | F25: 4000 | G25: 0.6
A26: 1001 | B26: 2000 | C26: 12 | D26: 192 | E26: 378 | F26: 12000 | G26: 0.2
A27: 2001 | B27: 3000 | C27: 16 | D27: 378 | E27: 512 | F27: 36000 | G27: 0.1
A28: 3001 | B28: 4000 | C28: 16 | D28: 512 | E28: 768 | F28: 64000 | G28: 0.1
A29: 4001 | B29: 5000 | C29: 24 | D29: 768 | E29: 1024 | F29: 128000 | G29: 0.1

Sheet Windows
A4: Стандарт | B4: Промислове середовище | D4: CPU | E4: RAM rec | F4: Кількість | G4: ОС | H4: Диск для ОС | J4: Диск для LDF, TEMPDB | L4: Диск для MainData | N4: Диск для Content | P4: PageFile | R4: IOPS | T4: Lat. <=, mc
A5: К-ть ліцензій | B5: Сервери | C5: от ГГц >= | D5: Ядер | E5: Гб | H5: тип | I5: Гб | J5: тип | K5: Гб | L5: тип | M5: Гб | N5: тип | O5: Гб | P5: тип | Q5: Гб
B6: SQL | C6: 3.0 | D6: =IFERROR(VLOOKUP(A6,MSSQL!A2:E13,3,TRUE),"0") -> 0 | E6: =IFERROR(VLOOKUP(A6,MSSQL!A2:E13,5,TRUE),"0") -> 0 | F6: 1 | G6: Windows Server 2022 | H6: SSD | I6: 150 | J6: SSD | K6: 150* | L6: SSD | M6: 300* | N6: SATA | O6: 200* | R6: =IFERROR(VLOOKUP(A6,MSSQL!A2:G13,6,TRUE),"0") -> 0 | S6: 50r/50w | T6: =IFERROR(VLOOKUP(A6,MSSQL!A2:G13,7,TRUE),"0") -> 0
B7: Сервери додатків | C7: =SUMIFS($D$26:$D$37,$A$26:$A$37,"<="&A6,$B$26:$B$37,">="&A6) -> 0 | D7: =SUMIFS($E$26:$E$37,$A$26:$A$37,"<="&A6,$B$26:$B$37,">="&A6) -> 0 | E7: =SUMIFS($H$26:$H$37,$A$26:$A$37,"<="&A6,$B$26:$B$37,">="&A6) -> 0 | F7: =SUMIFS($C$26:$C$37,$A$26:$A$37,"<="&A6,$B$26:$B$37,">="&A6) -> 0 | G7: Windows Server 2022 | H7: SSD | I7: 150 | P7: SSD | Q7: =CEILING(E7*4,10) -> 0 | R7: =SUMIFS($F$26:$F$37,$A$26:$A$37,"<="&A6,$B$26:$B$37,">="&A6) -> 0 | S7: 30r/70w
B8: Веб сервери (IIS) | C8: =SUMIFS($D$41:$D$49,$A$41:$A$49,"<="&A6,$B$41:$B$49,">="&A6) -> 0 | D8: =SUMIFS($E$41:$E$49,$A$41:$A$49,"<="&A6,$B$41:$B$49,">="&A6) -> 0 | E8: =SUMIFS($H$41:$H$49,$A$41:$A$49,"<="&A6,$B$41:$B$49,">="&A6) -> 0 | F8: =SUMIFS($C$41:$C$49,$A$41:$A$49,"<="&A6,$B$41:$B$49,">="&A6) -> 0 | G8: Windows Server 2022 | H8: SSD | I8: 150 | P8: SSD | Q8: =CEILING(E8*4,10) -> 0 | R8: =SUMIFS($F$41:$F$49,$A$41:$A$49,"<="&A6,$B$41:$B$49,">="&A6) -> 0 | S8: 70r/30w
A14: Документообіг | B14: Промислове середовище | D14: CPU | E14: RAM rec | F14: Кількість | G14: ОС | H14: Диск для ОС | J14: Диск для LDF, TEMPDB | L14: Диск для MainData | N14: Диск для Content | P14: PageFile | R14: IOPS | T14: Lat. <=, mc
A15: К-ть ліцензій | B15: Сервери | C15: от ГГц >= | D15: Ядер | E15: Гб | H15: тип | I15: Гб | J15: тип | K15: Гб | L15: тип | M15: Гб | N15: тип | O15: Гб | P15: тип | Q15: Гб
B16: SQL | C16: 3.0 | D16: =IFERROR(VLOOKUP(A16,MSSQL!A18:E29,3,TRUE),"0") -> 0 | E16: =IFERROR(VLOOKUP(A16,MSSQL!A18:E29,5,TRUE),"0") -> 0 | F16: 1 | G16: Windows Server 2022 | H16: SSD | I16: 150 | J16: SSD | K16: 150* | L16: SSD | M16: 300* | N16: SATA | O16: 200* | R16: =IFERROR(VLOOKUP(A16,MSSQL!A18:G29,6,TRUE),"0") -> 0 | S16: 50r/50w | T16: =IFERROR(VLOOKUP(A16,MSSQL!A18:G29,7,TRUE),"0") -> 0
B17: Сервери додатків | C17: =SUMIFS($D$52:$D$63,$A$52:$A$63,"<="&A16,$B$52:$B$63,">="&A16) -> 0 | D17: =SUMIFS($E$52:$E$63,$A$52:$A$63,"<="&A16,$B$52:$B$63,">="&A16) -> 0 | E17: =SUMIFS($H$52:$H$63,$A$52:$A$63,"<="&A16,$B$52:$B$63,">="&A16) -> 0 | F17: =SUMIFS($C$52:$C$63,$A$52:$A$63,"<="&A16,$B$52:$B$63,">="&A16) -> 0 | G17: Windows Server 2022 | H17: SSD | I17: 150 | P17: SSD | Q17: =CEILING(E17*4,10) -> 0 | R17: =SUMIFS($F$52:$F$63,$A$52:$A$63,"<="&A16,$B$52:$B$63,">="&A16) -> 0 | S17: 30r/70w
B18: Веб сервери (IIS) | C18: =SUMIFS($D$41:$D$49,$A$41:$A$49,"<="&A16,$B$41:$B$49,">="&A16) -> 0 | D18: =SUMIFS($E$41:$E$49,$A$41:$A$49,"<="&A16,$B$41:$B$49,">="&A16) -> 0 | E18: =SUMIFS($H$41:$H$49,$A$41:$A$49,"<="&A16,$B$41:$B$49,">="&A16) -> 0 | F18: =SUMIFS($C$41:$C$49,$A$41:$A$49,"<="&A16,$B$41:$B$49,">="&A16) -> 0 | G18: Windows Server 2022 | H18: SSD | I18: 150 | P18: SSD | Q18: =CEILING(E18*4,10) -> 0 | R18: =SUMIFS($F$41:$F$49,$A$41:$A$49,"<="&A16,$B$41:$B$49,">="&A16) -> 0 | S18: 70r/30w
A24: AppServers | B24: Стандарт
A25: Мін ліцензій | B25: Макс ліцензій | C25: К-сть серверів | D25: GHz | E25: CPU | F25: IOPS | G25: RAM_Min | H25: RAM_Rec
A26: 1 | B26: 10 | C26: 1 | D26: 2 | E26: 4 | F26: 250 | G26: 6 | H26: 8
A27: 11 | B27: 25 | C27: 1 | D27: 2.4 | E27: 4 | F27: 250 | G27: 12 | H27: 16
A28: 26 | B28: 50 | C28: 1 | D28: 2.4 | E28: 4 | F28: 500 | G28: 16 | H28: 24
A29: 51 | B29: 100 | C29: 2 | D29: 2.4 | E29: 4 | F29: 500 | G29: 16 | H29: 24
A30: 101 | B30: 200 | C30: 4 | D30: 2.4 | E30: 4 | F30: 500 | G30: 16 | H30: 24
A31: 201 | B31: 350 | C31: 7 | D31: 2.4 | E31: 4 | F31: 500 | G31: 16 | H31: 24
A32: 351 | B32: 500 | C32: 10 | D32: 2.4 | E32: 4 | F32: 500 | G32: 16 | H32: 24
A33: 501 | B33: 1000 | C33: 20 | D33: 2.4 | E33: 4 | F33: 500 | G33: 16 | H33: 24
A34: 1001 | B34: 2000 | C34: 40 | D34: 2.4 | E34: 4 | F34: 500 | G34: 16 | H34: 24
A35: 2001 | B35: 3000 | C35: 60 | D35: 2.4 | E35: 4 | F35: 500 | G35: 16 | H35: 24
A36: 3001 | B36: 4000 | C36: 80 | D36: 2.4 | E36: 4 | F36: 500 | G36: 16 | H36: 24
A37: 4001 | B37: 5000 | C37: 100 | D37: 2.4 | E37: 4 | F37: 500 | G37: 16 | H37: 24
A39: WebServers | B39: Стандарт
A40: Мін ліцензій | B40: Макс ліцензій | C40: К-сть серверів | D40: GHz | E40: CPU | F40: IOPS | G40: RAM_Min | H40: RAM_Rec
A41: 1 | B41: 50 | C41: 1 | D41: 2 | E41: 4 | F41: 200 | G41: 4 | H41: 6
A42: 51 | B42: 100 | C42: 1 | D42: 2 | E42: 4 | F42: 200 | G42: 6 | H42: 8
A43: 101 | B43: 200 | C43: 1 | D43: 2.2 | E43: 4 | F43: 200 | G43: 8 | H43: 14
A44: 201 | B44: 400 | C44: 1 | D44: 2.2 | E44: 4 | F44: 200 | G44: 14 | H44: 18
A45: 401 | B45: 800 | C45: 2 | D45: 2.2 | E45: 4 | F45: 200 | G45: 14 | H45: 18
A46: 801 | B46: 1600 | C46: 4 | D46: 2.2 | E46: 4 | F46: 200 | G46: 14 | H46: 18
A47: 1601 | B47: 3200 | C47: 8 | D47: 2.2 | E47: 4 | F47: 200 | G47: 14 | H47: 18
A48: 3201 | B48: 6400 | C48: 16 | D48: 2.2 | E48: 4 | F48: 200 | G48: 14 | H48: 18
A49: 6401 | B49: 12800 | C49: 32 | D49: 2.2 | E49: 4 | F49: 200 | G49: 14 | H49: 18
A51: AppServers | B51: Документообіг
A52: Мін ліцензій | B52: Макс ліцензій | C52: К-сть серверів | D52: GHz | E52: CPU | F52: IOPS | G52: RAM_Min | H52: RAM_Rec
A53: 1 | B53: 10 | C53: 1 | D53: 2.4 | E53: 4 | F53: 250 | G53: 6 | H53: 8
A54: 11 | B54: 25 | C54: 1 | D54: 2.4 | E54: 4 | F54: 250 | G54: 12 | H54: 16
A55: 26 | B55: 50 | C55: 1 | D55: 2.4 | E55: 4 | F55: 1200 | G55: 24 | H55: 32
...
