Workbook

Sheet Prod 8000
C1: Значення
B2: Кількість конкурентних ліцензій | C2: 50 конк.ліц. | D2: 8000 корист. порталу
B4: Перелік VM
B7: VM Kubernetes
B8: Роль | C8: CPU, ядра від 3.2 ГГц | D8: RAM, GB | E8: Disk | G8: Кількість нод | H8: OS
E9: Тип | F9: GB
B10: Мастер нода | C10: 2 | D10: 4 | E10: ssd | F10: 100 | G10: 5 | H10: Ubuntu 24.04 LTS
B11: Робоча нода | C11: 8 | D11: 32 | E11: ssd | F11: 150 | G11: 5 | H11: Ubuntu 24.04 LTS
B14: VM Linux
B15: Роль | C15: CPU, ядра від 3.2 ГГц | D15: RAM, GB | E15: Disk | G15: Кількість нод | H15: Disk | O15: MiB /s | P15: OS/Software
E16: ОС | H16: MainData | J16: ContentData | L16: IOPS | N16: Latency <=, mc
E17: Тип | F17: GB | H17: Тип | I17: GB** | J17: Тип | K17: GB**
B18: СКБД* (PostgreSQL) | C18: 10 | D18: 64 | E18: ssd | F18: 150 | G18: 2 | H18: ssd | I18: 200 | J18: sata | K18: 300 | L18: 50r/50w | M18: 10000 | N18: 1 | O18: 800 | P18: Ubuntu 24.04 LTS
B20: Дисковий простір:
B21: **Наведені розміри дисків розраховані для початкового розгортання. Подальше розширення виконується відповідно до обсягу завантажених даних.
M22: AZURE payg | N22: AZURE 3-y
B23: Мережеві вимоги: | J23: vCPU | K23: =(C10*G10+C11*G11+C18*2)*3.2 -> 224 | M23: 2334 | N23: 1800
B24: Мінімальна пропускна здатність мережі між віртуальними машинами: 1 Gb/s. | J24: vRAM | K24: =D10*G10+D11*G11+D18*G18 -> 308 | M24: =M23*44.14 -> 103022.76 | N24: =N23*44.14 -> 79452
J25: vHDD (80000 IOPS ) | K25: =G11*F11+(150+200+300)*G18 -> 2050
B26: Ресурси сервісу сегментації (початкова конфігурація, вже додані до опису ресурсів): | J26: vHDD (5000 IOPS ) | K26: =G10*F10 -> 500
B27: CPU: 4 vCPU
B28: RAM: 6 ГБ
B29: Примітка: Продуктивність обробки відеоматеріалу прямо залежить від виділених обчислювальних ресурсів. Масштабування можливе за потреби.
A35: 1 | B35: кількість | C35: NAME | D35: CPU_REQ | E35: MEM_REQ | F35: CPU_LIM | G35: MEM_LIM / Gi(Mb) | H35: CPU | I35: MEM
A36: 1 | B36: =A36*$A$35 -> 1 | C36: itnet2-prod-as-robot | D36: 500m | E36: 8Gi | F36: 3 | G36: 14 | H36: =F36*B36 -> 3 | I36: =G36*B36 -> 14
A37: 1 | B37: =A37*$A$35 -> 1 | C37: itnet2-prod-as-robot-localsql | D37: 500m | E37: 8Gi | F37: 1 | G37: 8 | H37: =F37*B37 -> 1 | I37: =G37*B37 -> 8
A38: 1 | B38: =A38*$A$35 -> 1 | C38: appplayer-commonappplayer | D38: 50m | E38: 30Mi | F38: 0.2 | G38: 0.5 | H38: =F38*B38 -> 0.2 | I38: =G38*B38 -> 0.5
A39: 1 | B39: =A39*$A$35 -> 1 | C39: employee-assessment-webapp | D39: 100m | E39: 614Mi | F39: 0.3 | G39: 0.614 | H39: =F39*B39 -> 0.3 | I39: =G39*B39 -> 0.614
A40: 1 | B40: =A40*$A$35 -> 1 | C40: graphql | D40: 10m | E40: 570Mi | F40: 0.1 | G40: 1 | H40: =F40*B40 -> 0.1 | I40: =G40*B40 -> 1
A41: 2 | B41: =A41 -> 2 | C41: itnet2-as | D41: 200m | E41: 1Gi | F41: 2 | G41: 12 | H41: =F41*B41 -> 4 | I41: =G41*B41 -> 24
A42: 2 | B42: =A42 -> 2 | C42: itnet2-as-localsql | D42: 500m | E42: 1Gi | F42: 1 | G42: 8 | H42: =F42*B42 -> 2 | I42: =G42*B42 -> 16
A43: 1 | B43: =A43 -> 1 | C43: itnet2-as-redis | D43: 20m | E43: 50Mi | F43: 0.1 | G43: 0.5 | H43: =F43*B43 -> 0.1 | I43: =G43*B43 -> 0.5
A44: 1 | B44: =A44*$A$35 -> 1 | C44: lms | D44: 200m | E44: 300Mi | F44: 0.3 | G44: 0.6 | H44: =F44*B44 -> 0.3 | I44: =G44*B44 -> 0.6
A45: 1 | B45: =A45*$A$35 -> 1 | C45: lms-fileserver | D45: 100m | E45: 100Mi | F45: 0.4 | G45: 0.6 | H45: =F45*B45 -> 0.4 | I45: =G45*B45 -> 0.6
A46: 3 | B46: =A46*$A$35 -> 3 | C46: lms-it-graphql | D46: 100m | E46: 570Mi | F46: 1 | G46: 2 | H46: =F46*B46 -> 3 | I46: =G46*B46 -> 6
A47: 1 | B47: =A47 -> 1 | C47: lms-videoutilities | D47: 200m | E47: 300Mi | F47: 4 | G47: 6 | H47: =F47*B47 -> 4 | I47: =G47*B47 -> 6
A48: 2 | B48: =A48*$A$35 -> 2 | C48: login | D48: 300m | E48: 500Mi | F48: 0.5 | G48: 1 | H48: =F48*B48 -> 1 | I48: =G48*B48 -> 2
A49: 1 | B49: =A49*$A$35 -> 1 | C49: recruit-webapp | D49: 100m | E49: 100Mi | F49: 0.3 | G49: 0.6 | H49: =F49*B49 -> 0.3 | I49: =G49*B49 -> 0.6
A50: 1 | B50: 2 | C50: survey | D50: 10m | E50: 370Mi | F50: 0.1 | G50: 1 | H50: =F50*B50 -> 0.2 | I50: =G50*B50 -> 2
A51: 1 | B51: 2 | C51: survey-redis | D51: 10m | E51: 370Mi | F51: 1 | G51: 1 | H51: =F51*B51 -> 2 | I51: =G51*B51 -> 2
...

Sheet Prod 8000 cost
A1: {='тендер-прайс'!A1:D23} -> № | B1: Назва та параметри Послуги | C1: Одиниця тарифікації | D1: Ціна за одиницю, грн без ПДВ за місяць | E1: Кількість | F1: сумма, грн без ПДВ на міс.
A2: з/п | B2: 0 | C2: 0 | D2: 0
A3: 1 | B3: Обчислювальна потужність процесора (vCPU) SAP | C3: 1 GHz | D3: 123.53 | F3: =D3*E3 -> 0
A4: 2 | B4: Обчислювальна потужність процесора (vCPU) | C4: 1 GHz | D4: 114.38 | E4: =ROUNDUP('Prod 8000'!K23,0) -> 224 | F4: =D4*E4 -> 25621.12
A5: 3 | B5: Оперативна пам’ять (vRAM) SAP | C5: 1 GB | D5: 123.53 | F5: =D5*E5 -> 0
A6: 4 | B6: Оперативна пам’ять (vRAM) | C6: 1 GB | D6: 118.95 | E6: =ROUNDUP('Prod 8000'!K24,0) -> 308 | F6: =D6*E6 -> 36636.6
A7: 5 | B7: Накопичувачі та система зберігання (vHDD) 80000 IOPS SAP | C7: 1 GB | D7: 3.96 | F7: =D7*E7 -> 0
A8: 6 | B8: Накопичувачі та система зберігання (vHDD) 80000 IOPS | C8: 1 GB | D8: 3.84 | E8: =ROUNDUP('Prod 8000'!K25,0) -> 2050 | F8: =D8*E8 -> 7872
A9: 7 | B9: Накопичувачі та система зберігання (vHDD) 5000 IOPS SAP | C9: 1 GB | D9: 0.9 | F9: =D9*E9 -> 0
A10: 8 | B10: Накопичувані та система зберігання (vHDD) 5000 IOPS | C10: 1 GB | D10: 0.9 | E10: =ROUNDUP('Prod 8000'!K26,0) -> 500 | F10: =D10*E10 -> 450
A11: 9 | B11: Віртуальна мережа (VLAN) | C11: 1 екземпляр | D11: 137.25 | E11: 3 | F11: =D11*E11 -> 411.75
A12: 10 | B12: Послуга реплікації з використанням VMware Cloud Director Availability | C12: 1 VM | D12: 1.2 | F12: =D12*E12 -> 0
A13: 11 | B13: Безагентне (на рівні гіпервізору, без необхідності встановлення агентів в гостьові операційні системи) щоденне резервне копіювання даних з глибиною зберігання 31 день** | C13: 1 GB | D13: 2.75 | E13: =(E8+E10) -> 2550 | F13: =D13*E13 -> 7012.5
A14: 12 | B14: Послуга гео бекапування з використанням Veeam (м.Київ/м.Львів/AWS)*** | C14: 1 GB | D14: 5.3 | F14: =D14*E14 -> 0
A15: 13 | B15: Віртуальний маршрутизатор з функцією мережевого екрану та VPN | C15: 1 екземпляр | D15: 457.5 | E15: 1 | F15: =D15*E15 -> 457.5
A16: 14 | B16: Підключення до мережі Інтернет 1 Gb/s, зовнішній IP адрес | C16: підключення | D16: 3660 | E16: 2 | F16: =D16*E16 -> 7320
A17: 15 | B17: Підключення до мережі Інтернет 10 Gb/s з BGP-peering | C17: підключення | D17: 40000 | F17: =D17*E17 -> 0
A18: 16 | B18: Виділений канал пропускною здатністю 10G між ЦОД Виконавця та ЦОД Замовника, що знаходиться за адресою | C18: 1 канал | D18: 15000 | F18: =D18*E18 -> 0
A19: 17 | B19: Термінація виділеного каналу 1Gb/s (мідний порт) та презентація його у хмарний ландшафт Замовника | C19: порт | D19: 100 | F19: =D19*E19 -> 0
A20: 18 | B20: Термінація виділеного каналу 10Gb/s (оптичний порт) та презентація його у хмарний ландшафт Замовника | C20: порт | D20: 1500 | F20: =D20*E20 -> 0
A21: 19 | B21: Система моніторингу VMware Aria Operation | C21: 1 vCPU | D21: 32.03 | E21: =E4 -> 224 | F21: =D21*E21 -> 7174.72
A22: 20 | B22: 0 | C22: 1 GB vRAM | D22: 16.29 | E22: =E4 -> 224 | F22: =D22*E22 -> 3648.96
A23: 21 | B23: Віртуальна графічна пам'ять GPU на базі nVIDIA L40S з ліцензією AI Enterprise Essentials | C23: 48 GB | D23: 38000 | F23: =D23*E23 -> 0
F24: =SUM(F3:F23) -> 96605.15

Sheet Prod 80000
C1: Значення
B2: Кількість конкурентних ліцензій | C2: 50 конк.ліц. | D2: 80000 корист. порталу
B4: Перелік VM
B7: VM Kubernetes
B8: Роль | C8: CPU, ядра від 3.2 ГГц | D8: RAM, GB | E8: Disk | G8: Кількість нод | H8: OS
E9: Тип | F9: GB
B10: Мастер нода | C10: 2 | D10: 4 | E10: ssd | F10: 100 | G10: 1 | H10: Ubuntu 24.04 LTS
B11: Робоча нода | C11: 22 | D11: 70 | E11: ssd | F11: 150 | G11: 3 | H11: Ubuntu 24.04 LTS
B14: VM Linux
B15: Роль | C15: CPU, ядра від 3.2 ГГц | D15: RAM, GB | E15: Disk | G15: Кількість нод | H15: Disk | N15: MiB /s | O15: OS/Software
E16: ОС | H16: MainData | J16: ContentData | L16: IOPS 50r/50w | M16: Latency <=, mc
E17: Тип | F17: GB | H17: Тип | I17: GB** | J17: Тип | K17: GB**
B18: СКБД* (PostgreSQL) | C18: 16 | D18: 168 | E18: ssd | F18: 150 | G18: 3 | H18: ssd | I18: 200 | J18: sata | K18: 300 | L18: 10000 | M18: 1 | N18: 800 | O18: Ubuntu 24.04 LTS
B20: Дисковий простір:
B21: **Наведені розміри дисків розраховані для початкового розгортання. Подальше розширення виконується відповідно до обсягу завантажених даних.
M22: AZURE payg | N22: AZURE 3-y
B23: Мережеві вимоги: | J23: vCPU | K23: =(C10*G10+C11*G11+C18*G18)*3.2 -> 371.2 | M23: 2334 | N23: 1800
B24: Мінімальна пропускна здатність мережі між віртуальними машинами: 1 Gb/s. | J24: vRAM | K24: =D10*G10+D11*G11+D18*G18 -> 718 | M24: =M23*44.14 -> 103022.76 | N24: =N23*44.14 -> 79452
J25: vHDD (80000 IOPS ) | K25: =G11*F11+(150+200+300)*G18 -> 2400
B26: Ресурси сервісу сегментації (початкова конфігурація, вже додані до опису ресурсів): | J26: vHDD (5000 IOPS ) | K26: =G10*F10 -> 100
B27: CPU: 4 vCPU
B28: RAM: 6 ГБ
B29: Примітка: Продуктивність обробки відеоматеріалу прямо залежить від виділених обчислювальних ресурсів. Масштабування можливе за потреби.
A35: 3 | B35: кількість | C35: NAME | D35: CPU_REQ | E35: MEM_REQ | F35: CPU_LIM | G35: MEM_LIM / Gi(Mb) | H35: CPU | I35: MEM
A36: 1 | B36: =A36*$A$35 -> 3 | C36: itnet2-prod-as-robot | D36: 500m | E36: 8Gi | F36: 3 | G36: 14 | H36: =F36*B36 -> 9 | I36: =G36*B36 -> 42
A37: 1 | B37: =A37*$A$35 -> 3 | C37: itnet2-prod-as-robot-localsql | D37: 500m | E37: 8Gi | F37: 1 | G37: 8 | H37: =F37*B37 -> 3 | I37: =G37*B37 -> 24
A38: 1 | B38: =A38*$A$35 -> 3 | C38: appplayer-commonappplayer | D38: 50m | E38: 30Mi | F38: 0.2 | G38: 0.5 | H38: =F38*B38 -> 0.6 | I38: =G38*B38 -> 1.5
A39: 1 | B39: =A39*$A$35 -> 3 | C39: employee-assessment-webapp | D39: 100m | E39: 614Mi | F39: 0.3 | G39: 0.614 | H39: =F39*B39 -> 0.9 | I39: =G39*B39 -> 1.842
A40: 1 | B40: =A40*$A$35 -> 3 | C40: graphql | D40: 10m | E40: 570Mi | F40: 0.1 | G40: 1 | H40: =F40*B40 -> 0.3 | I40: =G40*B40 -> 3
A41: 2 | B41: =A41 -> 2 | C41: itnet2-as | D41: 200m | E41: 1Gi | F41: 2 | G41: 12 | H41: =F41*B41 -> 4 | I41: =G41*B41 -> 24
A42: 2 | B42: =A42 -> 2 | C42: itnet2-as-localsql | D42: 500m | E42: 1Gi | F42: 1 | G42: 8 | H42: =F42*B42 -> 2 | I42: =G42*B42 -> 16
A43: 1 | B43: =A43 -> 1 | C43: itnet2-as-redis | D43: 20m | E43: 50Mi | F43: 0.1 | G43: 0.5 | H43: =F43*B43 -> 0.1 | I43: =G43*B43 -> 0.5
A44: 1 | B44: =A44*$A$35 -> 3 | C44: lms | D44: 200m | E44: 300Mi | F44: 0.3 | G44: 0.6 | H44: =F44*B44 -> 0.9 | I44: =G44*B44 -> 1.8
A45: 1 | B45: =A45*$A$35 -> 3 | C45: lms-fileserver | D45: 100m | E45: 100Mi | F45: 0.4 | G45: 0.6 | H45: =F45*B45 -> 1.2 | I45: =G45*B45 -> 1.8
A46: 3 | B46: =A46*$A$35 -> 9 | C46: lms-it-graphql | D46: 100m | E46: 570Mi | F46: 1 | G46: 2 | H46: =F46*B46 -> 9 | I46: =G46*B46 -> 18
A47: 1 | B47: =A47 -> 1 | C47: lms-videoutilities | D47: 200m | E47: 300Mi | F47: 4 | G47: 6 | H47: =F47*B47 -> 4 | I47: =G47*B47 -> 6
A48: 2 | B48: =A48*$A$35 -> 6 | C48: login | D48: 300m | E48: 500Mi | F48: 0.5 | G48: 1 | H48: =F48*B48 -> 3 | I48: =G48*B48 -> 6
A49: 1 | B49: =A49*$A$35 -> 3 | C49: recruit-webapp | D49: 100m | E49: 100Mi | F49: 0.3 | G49: 0.6 | H49: =F49*B49 -> 0.9 | I49: =G49*B49 -> 1.8
A50: 1 | B50: 2 | C50: survey | D50: 10m | E50: 370Mi | F50: 0.1 | G50: 1 | H50: =F50*B50 -> 0.2 | I50: =G50*B50 -> 2
A51: 1 | B51: 2 | C51: survey-redis | D51: 10m | E51: 370Mi | F51: 1 | G51: 1 | H51: =F51*B51 -> 2 | I51: =G51*B51 -> 2
...

Sheet Prod 80000 cost
A1: {='тендер-прайс'!A1:D23} -> № | B1: Назва та параметри Послуги | C1: Одиниця тарифікації | D1: Ціна за одиницю, грн без ПДВ за місяць | E1: Кількість | F1: сумма, грн без ПДВ на міс.
A2: з/п | B2: 0 | C2: 0 | D2: 0
A3: 1 | B3: Обчислювальна потужність процесора (vCPU) SAP | C3: 1 GHz | D3: 123.53 | F3: =D3*E3 -> 0
A4: 2 | B4: Обчислювальна потужність процесора (vCPU) | C4: 1 GHz | D4: 114.38 | E4: =ROUNDUP('Prod 80000'!K23,0) -> 372 | F4: =D4*E4 -> 42549.36
A5: 3 | B5: Оперативна пам’ять (vRAM) SAP | C5: 1 GB | D5: 123.53 | F5: =D5*E5 -> 0
A6: 4 | B6: Оперативна пам’ять (vRAM) | C6: 1 GB | D6: 118.95 | E6: =ROUNDUP('Prod 80000'!K24,0) -> 718 | F6: =D6*E6 -> 85406.1
A7: 5 | B7: Накопичувачі та система зберігання (vHDD) 80000 IOPS SAP | C7: 1 GB | D7: 3.96 | F7: =D7*E7 -> 0
A8: 6 | B8: Накопичувачі та система зберігання (vHDD) 80000 IOPS | C8: 1 GB | D8: 3.84 | E8: =ROUNDUP('Prod 80000'!K25,0) -> 2400 | F8: =D8*E8 -> 9216
A9: 7 | B9: Накопичувачі та система зберігання (vHDD) 5000 IOPS SAP | C9: 1 GB | D9: 0.9 | F9: =D9*E9 -> 0
A10: 8 | B10: Накопичувані та система зберігання (vHDD) 5000 IOPS | C10: 1 GB | D10: 0.9 | E10: =ROUNDUP('Prod 80000'!K26,0) -> 100 | F10: =D10*E10 -> 90
A11: 9 | B11: Віртуальна мережа (VLAN) | C11: 1 екземпляр | D11: 137.25 | E11: 3 | F11: =D11*E11 -> 411.75
A12: 10 | B12: Послуга реплікації з використанням VMware Cloud Director Availability | C12: 1 VM | D12: 1.2 | F12: =D12*E12 -> 0
A13: 11 | B13: Безагентне (на рівні гіпервізору, без необхідності встановлення агентів в гостьові операційні системи) щоденне резервне копіювання даних з глибиною зберігання 31 день** | C13: 1 GB | D13: 2.75 | E13: =(E8+E10) -> 2500 | F13: =D13*E13 -> 6875
A14: 12 | B14: Послуга гео бекапування з використанням Veeam (м.Київ/м.Львів/AWS)*** | C14: 1 GB | D14: 5.3 | F14: =D14*E14 -> 0
A15: 13 | B15: Віртуальний маршрутизатор з функцією мережевого екрану та VPN | C15: 1 екземпляр | D15: 457.5 | E15: 1 | F15: =D15*E15 -> 457.5
A16: 14 | B16: Підключення до мережі Інтернет 1 Gb/s, зовнішній IP адрес | C16: підключення | D16: 3660 | E16: 2 | F16: =D16*E16 -> 7320
A17: 15 | B17: Підключення до мережі Інтернет 10 Gb/s з BGP-peering | C17: підключення | D17: 40000 | F17: =D17*E17 -> 0
A18: 16 | B18: Виділений канал пропускною здатністю 10G між ЦОД Виконавця та ЦОД Замовника, що знаходиться за адресою | C18: 1 канал | D18: 15000 | F18: =D18*E18 -> 0
A19: 17 | B19: Термінація виділеного каналу 1Gb/s (мідний порт) та презентація його у хмарний ландшафт Замовника | C19: порт | D19: 100 | F19: =D19*E19 -> 0
A20: 18 | B20: Термінація виділеного каналу 10Gb/s (оптичний порт) та презентація його у хмарний ландшафт Замовника | C20: порт | D20: 1500 | F20: =D20*E20 -> 0
A21: 19 | B21: Система моніторингу VMware Aria Operation | C21: 1 vCPU | D21: 32.03 | E21: =E4 -> 372 | F21: =D21*E21 -> 11915.16
A22: 20 | B22: 0 | C22: 1 GB vRAM | D22: 16.29 | E22: =E4 -> 372 | F22: =D22*E22 -> 6059.88
A23: 21 | B23: Віртуальна графічна пам'ять GPU на базі nVIDIA L40S з ліцензією AI Enterprise Essentials | C23: 48 GB | D23: 38000 | F23: =D23*E23 -> 0
F24: =SUM(F3:F23) -> 170300.75

Sheet тендер-прайс
A1: № | B1: Назва та параметри Послуги | C1: Одиниця тарифікації | D1: Ціна за одиницю, грн без ПДВ за місяць
A2: з/п
A3: 1 | B3: Обчислювальна потужність процесора (vCPU) SAP | C3: 1 GHz | D3: 123.53
A4: 2 | B4: Обчислювальна потужність процесора (vCPU) | C4: 1 GHz | D4: 114.38
A5: 3 | B5: Оперативна пам’ять (vRAM) SAP | C5: 1 GB | D5: 123.53
A6: 4 | B6: Оперативна пам’ять (vRAM) | C6: 1 GB | D6: 118.95
A7: 5 | B7: Накопичувачі та система зберігання (vHDD) 80000 IOPS SAP | C7: 1 GB | D7: 3.96
A8: 6 | B8: Накопичувачі та система зберігання (vHDD) 80000 IOPS | C8: 1 GB | D8: 3.84
A9: 7 | B9: Накопичувачі та система зберігання (vHDD) 5000 IOPS SAP | C9: 1 GB | D9: 0.9
A10: 8 | B10: Накопичувані та система зберігання (vHDD) 5000 IOPS | C10: 1 GB | D10: 0.9
A11: 9 | B11: Віртуальна мережа (VLAN) | C11: 1 екземпляр | D11: 137.25
A12: 10 | B12: Послуга реплікації з використанням VMware Cloud Director Availability | C12: 1 VM | D12: 1.2
A13: 11 | B13: Безагентне (на рівні гіпервізору, без необхідності встановлення агентів в гостьові операційні системи) щоденне резервне копіювання даних з глибиною зберігання 31 день** | C13: 1 GB | D13: 2.75
A14: 12 | B14: Послуга гео бекапування з використанням Veeam (м.Київ/м.Львів/AWS)*** | C14: 1 GB | D14: 5.3
... A21: 19 | B21: Система моніторингу VMware Aria Operation | C21: 1 vCPU | D21: 32.03
A22: 20 | C22: 1 GB vRAM | D22: 16.29
A23: 21 | B23: Віртуальна графічна пам'ять GPU на базі nVIDIA L40S з ліцензією AI Enterprise Essentials | C23: 48 GB | D23: 38000
